<?xml version="1.0" ?>
<!-- =================================================================================== -->
<!-- |    This document was autogenerated by xacro from R2.xacro                       | -->
<!-- |    EDITING THIS FILE BY HAND IS NOT RECOMMENDED                                 | -->
<!-- =================================================================================== -->
<robot name="R2">
  <ros2_control name = "Fourwheelcontrol" type = "system">
    <hardware>
      <plugin>ign_ros2_control/IgnitionSystem</plugin>
    </hardware>

    <!-- Wheel joints -->
    <joint name="left_wheel_joint_1">
      <command_interface name="velocity"/>
      <state_interface name="velocity"/>
      <state_interface name="position"/>
    </joint>

    <joint name="left_wheel_joint_2">
      <command_interface name="velocity"/>
      <state_interface name="velocity"/>
      <state_interface name="position"/>
    </joint>

    <joint name="right_wheel_joint_1">
      <command_interface name="velocity"/>
      <state_interface name="velocity"/>
      <state_interface name="position"/>
    </joint>

    <joint name="right_wheel_joint_2">
      <command_interface name="velocity"/>
      <state_interface name="velocity"/>
      <state_interface name="position"/>
    </joint>
  </ros2_control>

  <gazebo>
    <plugin filename="ign_ros2_control-system" name="ign_ros2_control::IgnitionROS2ControlPlugin">
      <robot_param>robot_description</robot_param>
      <robot_param_node>robot_state_publisher</robot_param_node>
      <parameters>/home/vignesh/robocon_ws/src/r2_description/config/diff_drive_controller.yaml</parameters>
    </plugin>
  </gazebo>

  <link name = "base_footprint">
  </link>

  <link name="base_link">
    <inertial>
      <origin rpy="0 0 0" xyz="-0.0013049994751027838 -0.3200000000000006 -0.34816479831103087"/>
      <mass value="14.834181921830558"/>
      <inertia ixx="0.899438" ixy="-0.0" ixz="-0.002499" iyy="2.099301" iyz="0.0" izz="1.202064"/>
    </inertial>
    <visual>
      <origin rpy="1.57 0 0" xyz="0 -0.35 0.35"/>
      <geometry>
        <mesh filename="package://r2_description/meshes/base_link.stl" scale="0.001 0.001 0.001"/>
      </geometry>
      <material name="aluminum">
        <color rgba="0.82 0.82 0.82 1.0"/>
      </material>
    </visual>
    <collision>
      <origin rpy="1.57 0 0" xyz="0 -0.35 0.35"/>
      <geometry>
        <mesh filename="package://r2_description/meshes/base_link.stl" scale="0.001 0.001 0.001"/>
      </geometry>
    </collision>
  </link>

  <link name="left_wheel_1_2">
    <inertial>
      <origin rpy="0 0 0" xyz="-0.024999999999999967 4.6629367034256575e-15 3.608224830031759e-16"/>
      <mass value="0.5208958093685518"/>
      <inertia ixx="0.001636" ixy="0.0" ixz="-0.0" iyy="0.000925" iyz="0.0" izz="0.000925"/>
    </inertial>
    <visual>
      <origin rpy="1.57 0 0" xyz="-0.395 -0.085 0.32"/>
      <geometry>
        <mesh filename="package://r2_description/meshes/left_wheel_1_2.stl" scale="0.001 0.001 0.001"/>
      </geometry>
      <material name="black">
        <color rgba="0.05 0.05 0.05 1.0"/>
      </material>
    </visual>
    <collision>
      <origin rpy="1.57 0 0" xyz="-0.395 -0.085 0.32"/>
      <geometry>
        <mesh filename="package://r2_description/meshes/left_wheel_1_2.stl" scale="0.001 0.001 0.001"/>
      </geometry>
    </collision>
  </link>
  <link name="lefft_wheel_2_1">
    <inertial>
      <origin rpy="0 0 0" xyz="0.024999999999999634 -2.7755575615628914e-16 4.232725281383409e-15"/>
      <mass value="0.5208958093685515"/>
      <inertia ixx="0.001636" ixy="0.0" ixz="0.0" iyy="0.000925" iyz="-0.0" izz="0.000925"/>
    </inertial>
    <visual>
      <origin rpy="1.57 0 0" xyz="0.395 -0.085 0.32"/>
      <geometry>
        <mesh filename="package://r2_description/meshes/left_wheel_2_1.stl" scale="0.001 0.001 0.001"/>
      </geometry>
      <material name="black">
        <color rgba="0.05 0.05 0.05 1.0"/>
      </material>
    </visual>
    <collision>
      <origin rpy="1.57 0 0" xyz="0.395 -0.085 0.32"/>
      <geometry>
        <mesh filename="package://r2_description/meshes/left_wheel_2_1.stl" scale="0.001 0.001 0.001"/>
      </geometry>
    </collision>
  </link>
  <link name="left_wheel_1_1">
    <inertial>
      <origin rpy="0 0 0" xyz="-0.024999999999999967 4.496403249731884e-15 4.440892098500626e-16"/>
      <mass value="0.5208958093685518"/>
      <inertia ixx="0.001636" ixy="-0.0" ixz="-0.0" iyy="0.000925" iyz="0.0" izz="0.000925"/>
    </inertial>
    <visual>
      <origin rpy="1.57 0 0" xyz="-0.395 -0.615 0.32"/>
      <geometry>
        <mesh filename="package://r2_description/meshes/left_wheel_1_1.stl" scale="0.001 0.001 0.001"/>
      </geometry>
      <material name="black">
        <color rgba="0.05 0.05 0.05 1.0"/>
      </material>
    </visual>
    <collision>
      <origin rpy="1.57 0 0" xyz="-0.395 -0.615 0.32"/>
      <geometry>
        <mesh filename="package://r2_description/meshes/left_wheel_1_1.stl" scale="0.001 0.001 0.001"/>
      </geometry>
    </collision>
  </link>

  <link name="left_wheel_1_3">
    <inertial>
      <origin rpy="0 0 0" xyz="0.02499999999999991 3.885780586188048e-16 -4.440892098500626e-15"/>
      <mass value="0.5208958093685518"/>
      <inertia ixx="0.001636" ixy="-0.0" ixz="0.0" iyy="0.000925" iyz="-0.0" izz="0.000925"/>
    </inertial>
    <visual>
      <origin rpy="1.57 0 0" xyz="0.395 -0.615 0.32"/>
      <geometry>
        <mesh filename="package://r2_description/meshes/left_wheel_1_3.stl" scale="0.001 0.001 0.001"/>
      </geometry>
      <material name="black">
        <color rgba="0.05 0.05 0.05 1.0"/>
      </material>
    </visual>
    <collision>
      <origin rpy="1.57 0 0" xyz="0.395 -0.615 0.32"/>
      <geometry>
        <mesh filename="package://r2_description/meshes/left_wheel_1_3.stl" scale="0.001 0.001 0.001"/>
      </geometry>
    </collision>
  </link>
  
  <joint name="base_joint" type = "fixed">
    <origin rpy="0 0 0" xyz="0 0 0.5"/>
    <parent link="base_footprint"/>
    <child link="base_link"/>
  </joint>
  <joint name="left_wheel_joint_1" type="continuous">
    <origin rpy="0 0 0" xyz="0.395 -0.265 0.03"/>
    <parent link="base_link"/>
    <child link="left_wheel_1_2"/>
    <axis xyz="1.0 0.0 0.0"/>
  </joint>
  <joint name="right_wheel_joint_1" type="continuous">
    <origin rpy="0 0 0" xyz="-0.395 -0.265 0.03"/>
    <parent link="base_link"/>
    <child link="lefft_wheel_2_1"/>
    <axis xyz="1.0 0.0 0.0"/>
  </joint>
  <joint name="left_wheel_joint_2" type="continuous">
    <origin rpy="0 0 0" xyz="0.395 0.265 0.03"/>
    <parent link="base_link"/>
    <child link="left_wheel_1_1"/>
    <axis xyz="1.0 0.0 0.0"/>
  </joint>
  <joint name="right_wheel_joint_2" type="continuous">
    <origin rpy="0 0 0" xyz="-0.395 0.265 0.03"/>
    <parent link="base_link"/>
    <child link="left_wheel_1_3"/>
    <axis xyz="1.0 0.0 0.0"/>
  </joint>
</robot>
