<?xml version="1.0" ?>
<robot name="R2" xmlns:xacro="http://www.ros.org/wiki/xacro">

<xacro:include filename="$(find r2_description)/urdf/materials.xacro" />
<xacro:include filename="$(find r2_description)/urdf/R2.trans" />
<xacro:include filename="$(find r2_description)/urdf/R2.gazebo" />
<link name="base_link">
  <inertial>
    <origin xyz="-0.0013049994751027838 -0.3200000000000006 -0.34816479831103087" rpy="0 0 0"/>
    <mass value="14.834181921830558"/>
    <inertia ixx="0.899438" iyy="2.099301" izz="1.202064" ixy="-0.0" iyz="0.0" ixz="-0.002499"/>
  </inertial>
  <visual>
    <origin xyz="0 0 0" rpy="0 0 0"/>
    <geometry>
      <mesh filename="package://r2_description/meshes/base_link.stl" scale="0.001 0.001 0.001"/>
    </geometry>
    <material name="silver"/>
  </visual>
  <collision>
    <origin xyz="0 0 0" rpy="0 0 0"/>
    <geometry>
      <mesh filename="package://r2_description/meshes/base_link.stl" scale="0.001 0.001 0.001"/>
    </geometry>
  </collision>
</link>

<link name="left_wheel_1_2">
  <inertial>
    <origin xyz="-0.024999999999999967 4.6629367034256575e-15 3.608224830031759e-16" rpy="0 0 0"/>
    <mass value="0.5208958093685518"/>
    <inertia ixx="0.001636" iyy="0.000925" izz="0.000925" ixy="0.0" iyz="0.0" ixz="-0.0"/>
  </inertial>
  <visual>
    <origin xyz="-0.42 0.32 0.085" rpy="0 0 0"/>
    <geometry>
      <mesh filename="package://r2_description/meshes/left_wheel_1_2.stl" scale="0.001 0.001 0.001"/>
    </geometry>
    <material name="silver"/>
  </visual>
  <collision>
    <origin xyz="-0.42 0.32 0.085" rpy="0 0 0"/>
    <geometry>
      <mesh filename="package://r2_description/meshes/left_wheel_1_2.stl" scale="0.001 0.001 0.001"/>
    </geometry>
  </collision>
</link>

<link name="lefft_wheel_2_1">
  <inertial>
    <origin xyz="0.024999999999999634 -2.7755575615628914e-16 4.232725281383409e-15" rpy="0 0 0"/>
    <mass value="0.5208958093685515"/>
    <inertia ixx="0.001636" iyy="0.000925" izz="0.000925" ixy="0.0" iyz="-0.0" ixz="0.0"/>
  </inertial>
  <visual>
    <origin xyz="0.42 0.32 0.085" rpy="0 0 0"/>
    <geometry>
      <mesh filename="package://r2_description/meshes/lefft_wheel_2_1.stl" scale="0.001 0.001 0.001"/>
    </geometry>
    <material name="silver"/>
  </visual>
  <collision>
    <origin xyz="0.42 0.32 0.085" rpy="0 0 0"/>
    <geometry>
      <mesh filename="package://r2_description/meshes/lefft_wheel_2_1.stl" scale="0.001 0.001 0.001"/>
    </geometry>
  </collision>
</link>

<link name="left_wheel_1_1">
  <inertial>
    <origin xyz="-0.024999999999999967 4.496403249731884e-15 4.440892098500626e-16" rpy="0 0 0"/>
    <mass value="0.5208958093685518"/>
    <inertia ixx="0.001636" iyy="0.000925" izz="0.000925" ixy="-0.0" iyz="0.0" ixz="-0.0"/>
  </inertial>
  <visual>
    <origin xyz="-0.42 0.32 0.615" rpy="0 0 0"/>
    <geometry>
      <mesh filename="package://r2_description/meshes/left_wheel_1_1.stl" scale="0.001 0.001 0.001"/>
    </geometry>
    <material name="silver"/>
  </visual>
  <collision>
    <origin xyz="-0.42 0.32 0.615" rpy="0 0 0"/>
    <geometry>
      <mesh filename="package://r2_description/meshes/left_wheel_1_1.stl" scale="0.001 0.001 0.001"/>
    </geometry>
  </collision>
</link>

<link name="left_wheel_1_3">
  <inertial>
    <origin xyz="0.02499999999999991 3.885780586188048e-16 -4.440892098500626e-15" rpy="0 0 0"/>
    <mass value="0.5208958093685518"/>
    <inertia ixx="0.001636" iyy="0.000925" izz="0.000925" ixy="-0.0" iyz="-0.0" ixz="0.0"/>
  </inertial>
  <visual>
    <origin xyz="0.42 0.32 0.615" rpy="0 0 0"/>
    <geometry>
      <mesh filename="package://r2_description/meshes/left_wheel_1_3.stl" scale="0.001 0.001 0.001"/>
    </geometry>
    <material name="silver"/>
  </visual>
  <collision>
    <origin xyz="0.42 0.32 0.615" rpy="0 0 0"/>
    <geometry>
      <mesh filename="package://r2_description/meshes/left_wheel_1_3.stl" scale="0.001 0.001 0.001"/>
    </geometry>
  </collision>
</link>

<joint name="Revolute 5" type="continuous">
  <origin xyz="0.42 -0.32 -0.085" rpy="0 0 0"/>
  <parent link="base_link"/>
  <child link="left_wheel_1_2"/>
  <axis xyz="1.0 0.0 0.0"/>
</joint>

<joint name="Revolute 6" type="continuous">
  <origin xyz="-0.42 -0.32 -0.085" rpy="0 0 0"/>
  <parent link="base_link"/>
  <child link="lefft_wheel_2_1"/>
  <axis xyz="-1.0 0.0 0.0"/>
</joint>

<joint name="Revolute 7" type="continuous">
  <origin xyz="0.42 -0.32 -0.615" rpy="0 0 0"/>
  <parent link="base_link"/>
  <child link="left_wheel_1_1"/>
  <axis xyz="1.0 0.0 0.0"/>
</joint>

<joint name="Revolute 8" type="continuous">
  <origin xyz="-0.42 -0.32 -0.615" rpy="0 0 0"/>
  <parent link="base_link"/>
  <child link="left_wheel_1_3"/>
  <axis xyz="-1.0 0.0 0.0"/>
</joint>

</robot>
