<?xml version="1.0" ?>
<!-- =================================================================================== -->
<!-- |    This document was autogenerated by xacro from R2.xacro                       | -->
<!-- |    EDITING THIS FILE BY HAND IS NOT RECOMMENDED                                 | -->
<!-- =================================================================================== -->
<robot name="R2">
  <ros2_control name = "DiffDrivecontrol" type = "system">
    <hardware>
      <plugin>gazebo_ros2_control/GazeboSystem</plugin>
      <params name= "calculate_dynamics">true</params>
    </hardware>

    <!-- Wheel joints -->
    <joint name="left_wheel_joint_1">
      <command_interface name="velocity"/>
      <state_interface name="velocity"/>
      <state_interface name="position"/>
    </joint>

    <joint name="left_wheel_joint_2">
      <command_interface name="velocity"/>
      <state_interface name="velocity"/>
      <state_interface name="position"/>
    </joint>

    <joint name="right_wheel_joint_1">
      <command_interface name="velocity"/>
      <state_interface name="velocity"/>
      <state_interface name="position"/>
    </joint>

    <joint name="right_wheel_joint_2">
      <command_interface name="velocity"/>
      <state_interface name="velocity"/>
      <state_interface name="position"/>
    </joint>

  </ros2_control>

  <link name = "base_footprint"/>

  <link name="base_link">
    <inertial>
      <origin rpy="0 0 0" xyz="-0.0013049994751027838 -0.3200000000000006 -0.34816479831103087"/>
      <mass value="14.834181921830558"/>
      <inertia ixx="0.899438" ixy="-0.0" ixz="-0.002499" iyy="2.099301" iyz="0.0" izz="1.202064"/>
    </inertial>
    <visual>
      <origin rpy="0 0 0" xyz="0 0 0"/>
      <geometry>
        <mesh filename="package://field_description/meshes/r2_chassis/base_link.stl" scale="0.001 0.001 0.001"/>
      </geometry>
      <material name="aluminum">
        <color rgba="0.82 0.82 0.82 1.0"/>
      </material>
    </visual>
    <collision>
      <origin rpy="0 0 0" xyz="0 0 0"/>
      <geometry>
        <mesh filename="package://field_description/meshes/r2_chassis/base_link.stl" scale="0.001 0.001 0.001"/>
      </geometry>
    </collision>
  </link>

  <link name="left_wheel_1_2">
    <inertial>
      <origin rpy="0 0 0" xyz="-0.024999999999999967 4.6629367034256575e-15 3.608224830031759e-16"/>
      <mass value="0.5208958093685518"/>
      <inertia ixx="0.001636" ixy="0.0" ixz="-0.0" iyy="0.000925" iyz="0.0" izz="0.000925"/>
    </inertial>
    <visual>
      <origin rpy="0 0 0" xyz="-0.42 0.32 0.085"/>
      <geometry>
        <mesh filename="package://field_description/meshes/r2_chassis/left_wheel_1_2.stl" scale="0.001 0.001 0.001"/>
      </geometry>
      <material name="black">
        <color rgba="0.05 0.05 0.05 1.0"/>
      </material>
    </visual>
    <collision>
      <origin rpy="0 0 0" xyz="-0.42 0.32 0.085"/>
      <geometry>
        <mesh filename="package://field_description/meshes/r2_chassis/left_wheel_1_2.stl" scale="0.001 0.001 0.001"/>
      </geometry>
    </collision>
  </link>
  <link name="lefft_wheel_2_1">
    <inertial>
      <origin rpy="0 0 0" xyz="0.024999999999999634 -2.7755575615628914e-16 4.232725281383409e-15"/>
      <mass value="0.5208958093685515"/>
      <inertia ixx="0.001636" ixy="0.0" ixz="0.0" iyy="0.000925" iyz="-0.0" izz="0.000925"/>
    </inertial>
    <visual>
      <origin rpy="0 0 0" xyz="0.42 0.32 0.085"/>
      <geometry>
        <mesh filename="package://field_description/meshes/r2_chassis/left_wheel_2_1.stl" scale="0.001 0.001 0.001"/>
      </geometry>
      <material name="black">
        <color rgba="0.05 0.05 0.05 1.0"/>
      </material>
    </visual>
    <collision>
      <origin rpy="0 0 0" xyz="0.42 0.32 0.085"/>
      <geometry>
        <mesh filename="package://field_description/meshes/r2_chassis/left_wheel_2_1.stl" scale="0.001 0.001 0.001"/>
      </geometry>
    </collision>
  </link>
  <link name="left_wheel_1_1">
    <inertial>
      <origin rpy="0 0 0" xyz="-0.024999999999999967 4.496403249731884e-15 4.440892098500626e-16"/>
      <mass value="0.5208958093685518"/>
      <inertia ixx="0.001636" ixy="-0.0" ixz="-0.0" iyy="0.000925" iyz="0.0" izz="0.000925"/>
    </inertial>
    <visual>
      <origin rpy="0 0 0" xyz="-0.42 0.32 0.615"/>
      <geometry>
        <mesh filename="package://field_description/meshes/r2_chassis/left_wheel_1_1.stl" scale="0.001 0.001 0.001"/>
      </geometry>
      <material name="black">
        <color rgba="0.05 0.05 0.05 1.0"/>
      </material>
    </visual>
    <collision>
      <origin rpy="0 0 0" xyz="-0.42 0.32 0.615"/>
      <geometry>
        <mesh filename="package://field_description/meshes/r2_chassis/left_wheel_1_1.stl" scale="0.001 0.001 0.001"/>
      </geometry>
    </collision>
  </link>

  <link name="left_wheel_1_3">
    <inertial>
      <origin rpy="0 0 0" xyz="0.02499999999999991 3.885780586188048e-16 -4.440892098500626e-15"/>
      <mass value="0.5208958093685518"/>
      <inertia ixx="0.001636" ixy="-0.0" ixz="0.0" iyy="0.000925" iyz="-0.0" izz="0.000925"/>
    </inertial>
    <visual>
      <origin rpy="0 0 0" xyz="0.42 0.32 0.615"/>
      <geometry>
        <mesh filename="package://field_description/meshes/r2_chassis/left_wheel_1_3.stl" scale="0.001 0.001 0.001"/>
      </geometry>
      <material name="black">
        <color rgba="0.05 0.05 0.05 1.0"/>
      </material>
    </visual>
    <collision>
      <origin rpy="0 0 0" xyz="0.42 0.32 0.615"/>
      <geometry>
        <mesh filename="package://field_description/meshes/r2_chassis/left_wheel_1_3.stl" scale="0.001 0.001 0.001"/>
      </geometry>
    </collision>
  </link>
  
  <joint name="base_joint" type = "fixed">
    <origin rpy="1.5708 0 3.14" xyz="1.4 -5.25 0.446"/>
    <parent link="base_footprint"/>
    <child link="base_link"/>
  </joint>
  <joint name="left_wheel_joint_1" type="revolute">
    <origin rpy="0 0 0" xyz="0.42 -0.32 -0.085"/>
    <parent link="base_link"/>
    <child link="left_wheel_1_2"/>
    <limit effort="10.0" velocity="10.0" lower="-1" upper="1"/>
    <axis xyz="1.0 0.0 0.0"/>
  </joint>
  <joint name="right_wheel_joint_1" type="revolute">
    <origin rpy="0 0 0" xyz="-0.42 -0.32 -0.085"/>
    <parent link="base_link"/>
    <child link="lefft_wheel_2_1"/>
    <limit effort="10.0" velocity="10.0" lower="-1" upper="1"/>
    <axis xyz="-1.0 0.0 0.0"/>
  </joint>
  <joint name="left_wheel_joint_2" type="revolute">
    <origin rpy="0 0 0" xyz="0.42 -0.32 -0.615"/>
    <parent link="base_link"/>
    <child link="left_wheel_1_1"/>
    <limit effort="10.0" velocity="10.0" lower="-1" upper="1"/>
    <axis xyz="1.0 0.0 0.0"/>
  </joint>
  <joint name="right_wheel_joint_2" type="revolute">
    <origin rpy="0 0 0" xyz="-0.42 -0.32 -0.615"/>
    <parent link="base_link"/>
    <child link="left_wheel_1_3"/>
    <limit effort="10.0" velocity="10.0" lower="-1" upper="1"/>
    <axis xyz="-1.0 0.0 0.0"/>
  </joint>
</robot>
