<?xml version="1.0" ?>
<robot name="3_pivot_arm">

    <link name="base_link">
    <inertial>
        <origin xyz="-0.022105892523602927 -0.013747308393746297 0.10793488412433241" rpy="0 0 0"/>
        <mass value="6.572815330344555"/>
        <inertia ixx="0.094956" iyy="0.088875" izz="0.009815" ixy="0.0" iyz="-0.001046" ixz="1e-06"/>
    </inertial>
    <visual>
        <origin xyz="0 0 0" rpy="0 0 0"/>
        <geometry>
        <mesh filename="package://field_description/meshes/arm_meshes/base_link.stl" scale="0.001 0.001 0.001"/>
        </geometry>
        <material name="black">
            <color rgba="0.05 0.05 0.05 1.0"/>
        </material>
    </visual>
    <collision>
        <origin xyz="0 0 0" rpy="0 0 0"/>
        <geometry>
        <mesh filename="package://field_description/meshes/arm_meshes/base_link.stl" scale="0.001 0.001 0.001"/>
        </geometry>
    </collision>
    </link>

    <link name="arm_link_1_1">
    <inertial>
        <origin xyz="0.09735512688325568 -0.007477574085502821 -0.00018838692007583369" rpy="0 0 0"/>
        <mass value="4.022304137846002"/>
        <inertia ixx="0.002993" iyy="0.029916" izz="0.027931" ixy="0.001132" iyz="-3e-06" ixz="5e-05"/>
    </inertial>
    <visual>
        <origin xyz="0.023 -0.045866 -0.29" rpy="0 0 0"/>
        <geometry>
        <mesh filename="package://field_description/meshes/arm_meshes/arm_link_1_1.stl" scale="0.001 0.001 0.001"/>
        </geometry>
        <material name="black">
            <color rgba="0.05 0.05 0.05 1.0"/>
        </material>
    </visual>
    <collision>
        <origin xyz="0.023 -0.045866 -0.29" rpy="0 0 0"/>
        <geometry>
        <mesh filename="package://field_description/meshes/arm_meshes/arm_link_1_1.stl" scale="0.001 0.001 0.001"/>
        </geometry>
    </collision>
    </link>

    <link name="arm_link_2_1">
    <inertial>
        <origin xyz="0.2747534663550483 -0.03086570437430365 -0.04000048815108548" rpy="0 0 0"/>
        <mass value="0.5176042452171251"/>
        <inertia ixx="0.000342" iyy="0.003944" izz="0.003638" ixy="-0.0" iyz="-0.0" ixz="0.0"/>
    </inertial>
    <visual>
        <origin xyz="-0.1875 -0.06 -0.29" rpy="0 0 0"/>
        <geometry>
        <mesh filename="package://field_description/meshes/arm_meshes/arm_link_2_1.stl" scale="0.001 0.001 0.001"/>
        </geometry>
        <material name="black">
            <color rgba="0.05 0.05 0.05 1.0"/>
        </material>
    </visual>
    <collision>
        <origin xyz="-0.1875 -0.06 -0.29" rpy="0 0 0"/>
        <geometry>
        <mesh filename="package://field_description/meshes/arm_meshes/arm_link_2_1.stl" scale="0.001 0.001 0.001"/>
        </geometry>
    </collision>
    </link>

    <link name="arm_gripper_1">
    <inertial>
        <origin xyz="0.07146077310513621 0.02732666488627722 0.0008895119033990873" rpy="0 0 0"/>
        <mass value="1.0901417412103238"/>
        <inertia ixx="0.016655" iyy="0.0009" izz="0.017112" ixy="2.9e-05" iyz="1.9e-05" ixz="-6e-06"/>
    </inertial>
    <visual>
        <origin xyz="-0.4045 -0.037866 -0.289603" rpy="0 0 0"/>
        <geometry>
        <mesh filename="package://field_description/meshes/arm_meshes/arm_gripper_1.stl" scale="0.001 0.001 0.001"/>
        </geometry>
        <material name="base_grey">
            <color rgba="0.5 0.5 0.5 1.0"/>
        </material>
    </visual>
    <collision>
        <origin xyz="-0.4045 -0.037866 -0.289603" rpy="0 0 0"/>
        <geometry>
        <mesh filename="package://field_description/meshes/arm_meshes/arm_gripper_1.stl" scale="0.001 0.001 0.001"/>
        </geometry>
    </collision>
    </link>

    <link name="gripper_left_1">
    <inertial>
        <origin xyz="0.765006165427783 0.6698599000403074 -0.0818499489602274" rpy="0 0 0"/>
        <mass value="0.3875232114950809"/>
        <inertia ixx="0.000381" iyy="0.001428" izz="0.001176" ixy="0.0001" iyz="2e-06" ixz="-1.6e-05"/>
    </inertial>
    <visual>
        <origin xyz="-0.54 -0.254 -0.29" rpy="0 0 0"/>
        <geometry>
        <mesh filename="package://field_description/meshes/arm_meshes/gripper_left_1.stl" scale="0.001 0.001 0.001"/>
        </geometry>
        <material name="base_grey">
            <color rgba="0.5 0.5 0.5 1.0"/>
        </material>
    </visual>
    <collision>
        <origin xyz="-0.54 -0.254 -0.29" rpy="0 0 0"/>
        <geometry>
        <mesh filename="package://field_description/meshes/arm_meshes/gripper_left_1.stl" scale="0.001 0.001 0.001"/>
        </geometry>
    </collision>
    </link>

    <link name="gripper_right_1">
    <inertial>
        <origin xyz="0.7696682848917958 0.7001387186846196 -0.08492686759124102" rpy="0 0 0"/>
        <mass value="0.3763901925737342"/>
        <inertia ixx="0.000374" iyy="0.001427" izz="0.001177" ixy="-0.000103" iyz="-2e-06" ixz="-1.6e-05"/>
    </inertial>
    <visual>
        <origin xyz="-0.54 0.118 -0.29" rpy="0 0 0"/>
        <geometry>
        <mesh filename="package://field_description/meshes/arm_meshes/gripper_right_1.stl" scale="0.001 0.001 0.001"/>
        </geometry>
        <material name="base_grey">
            <color rgba="0.5 0.5 0.5 1.0"/>
        </material>
    </visual>
    <collision>
        <origin xyz="-0.54 0.118 -0.29" rpy="0 0 0"/>
        <geometry>
        <mesh filename="package://field_description/meshes/arm_meshes/gripper_right_1.stl" scale="0.001 0.001 0.001"/>
        </geometry>
    </collision>
    </link>

    <joint name="arm_base" type="continuous">
    <origin xyz="-0.023 0.045866 0.29" rpy="0 0 0"/>
    <parent link="base_link"/>
    <child link="arm_link_1_1"/>
    <axis xyz="0.0 1.0 0.0"/>
    </joint>

    <joint name="arm_link_joint_1" type="continuous">
    <origin xyz="0.21 0.013866 0" rpy="0 0 0"/>
    <parent link="arm_link_1_1"/>
    <child link="arm_link_2_1"/>
    <axis xyz="0.0 1.0 0.0"/>
    </joint>

    <joint name="arm_link_joint_2" type="continuous">
    <origin xyz="0.217 -0.02 0" rpy="0 0 0"/>
    <parent link="arm_link_2_1"/>
    <child link="arm_gripper_1"/>
    <axis xyz="0.0 -1.0 0.0"/>
    </joint>

    <joint name="gripper_joint_left" type="continuous">
    <origin xyz=" 0.135 0.216 0" rpy="0 0 0"/>
    <parent link="arm_gripper_1"/>
    <child link="gripper_left_1"/>
    <axis xyz="0.0 0.0 1.0"/>
    </joint>

    <joint name="gripper_joint_right" type="continuous">
    <origin xyz="0.135 -0.155 0" rpy="0 0 3.14"/>
    <parent link="arm_gripper_1"/>
    <child link="gripper_right_1"/>
    <axis xyz="0.0 0.0 1.0"/>
    </joint>

</robot>