<?xml version="1.0" ?>
<robot name="Track_bot">

    <link name="driver_wheel_1_left">
        <inertial>
            <origin xyz="-0.545 0.63 0.21" rpy="0 0 0"/>
            <mass value="4.363398"/>
            <inertia ixx="0.01121" iyy="0.01282" izz="0.01121"
                    ixy="1.16e-10" ixz="-6.19e-10" iyz="-1.44e-10"/>
        </inertial>
        <visual>
            <origin xyz="0.545 -0.6 -0.21" rpy="0 0 0"/>
            <geometry>
            <mesh filename="package://field_description/meshes/track_bot_meshes/driver_wheel_1_left.stl"
                    scale="0.001 0.001 0.001"/>
            </geometry>
            <material name="black">
                <color rgba="0.05 0.05 0.05 1.0"/>
            </material>
        </visual>
        <collision>
            <origin xyz="0.545 -0.6 -0.21" rpy="0 0 0"/>
            <geometry>
            <mesh filename="package://field_description/meshes/track_bot_meshes/driver_wheel_1_left.stl"
                    scale="0.001 0.001 0.001"/>
            </geometry>
        </collision>
    </link>

    <link name="driven_wheel_2_left">
        <inertial>
            <origin xyz="-0.675056 0.63 0.07" rpy="0 0 0"/>
            <mass value="4.320672"/>
            <inertia ixx="0.01115" iyy="0.01282" izz="0.01115"
                    ixy="-6.18e-15" ixz="-6e-12" iyz="0"/>
        </inertial>
        <visual>
            <origin xyz="0.675 -0.6 -0.07" rpy="0 0 0"/>
            <geometry>
            <mesh filename="package://field_description/meshes/track_bot_meshes/driven_wheel_2_left.stl"
                    scale="0.001 0.001 0.001"/>
            </geometry>
            <material name="black">
                <color rgba="0.05 0.05 0.05 1.0"/>
            </material>
        </visual>
        <collision>
            <origin xyz="0.675 -0.6 -0.07" rpy="0 0 0"/>
            <geometry>
            <mesh filename="package://field_description/meshes/track_bot_meshes/driven_wheel_2_left.stl"
                    scale="0.001 0.001 0.001"/>
            </geometry>
        </collision>
    </link>

    <link name="driven_wheel_3_left">
        <inertial>
            <origin xyz="-0.845055 0.63 0.04" rpy="0 0 0"/>
            <mass value="1.083031"/>
            <inertia ixx="0.001609" iyy="0.000797" izz="0.001609"
                    ixy="-9e-17" ixz="-4.8e-11" iyz="-3.9e-17"/>
        </inertial>
        <visual>
            <origin xyz="0.845 -0.6 -0.04" rpy="0 0 0"/>
            <geometry>
            <mesh filename="package://field_description/meshes/track_bot_meshes/driven_wheel_3_left.stl"
                    scale="0.001 0.001 0.001"/>
            </geometry>
            <material name="black">
                <color rgba="0.05 0.05 0.05 1.0"/>
            </material>
        </visual>
        <collision>
            <origin xyz="0.845 -0.6 -0.04" rpy="0 0 0"/>
            <geometry>
            <mesh filename="package://field_description/meshes/track_bot_meshes/driven_wheel_3_left.stl"
                    scale="0.001 0.001 0.001"/>
            </geometry>
        </collision>
    </link>

    <link name="drive_wheel_left">
        <inertial>
            <origin xyz="-1.025 0.630472 0.069998" rpy="0 0 0"/>
            <mass value="5.434623"/>
            <inertia ixx="0.01381" iyy="0.01734" izz="0.01381"
                    ixy="1.39e-7" ixz="-6.9e-8" iyz="1.63e-7"/>
        </inertial>
        <visual>
            <origin xyz="1.025 -0.6 -0.07" rpy="0 0 0"/>
            <geometry>
            <mesh filename="package://field_description/meshes/track_bot_meshes/drive_wheel_left.stl"
                    scale="0.001 0.001 0.001"/>
            </geometry>
            <material name="black">
                <color rgba="0.05 0.05 0.05 1.0"/>
            </material>
        </visual>
        <collision>
            <origin xyz="1.025 -0.6 -0.07" rpy="0 0 0"/>
            <geometry>
            <mesh filename="package://field_description/meshes/track_bot_meshes/drive_wheel_left.stl"
                    scale="0.001 0.001 0.001"/>
            </geometry>
        </collision>
    </link>

    <link name="driven_wheel_1_right">
        <inertial>
            <origin xyz="-0.545 -0.072 0.21" rpy="0 0 0"/>
            <mass value="0.583428"/>
            <inertia ixx="0.001506" iyy="0.001731" izz="0.001506"
                    ixy="4.2e-11" ixz="2.7e-10" iyz="6e-11"/>
        </inertial>
        <visual>
            <origin xyz="0.545 0.04 -0.21" rpy="0 0 0"/>
            <geometry>
            <mesh filename="package://field_description/meshes/track_bot_meshes/driven_wheel_1_right.stl"
                    scale="0.001 0.001 0.001"/>
            </geometry>
            <material name="black">
                <color rgba="0.05 0.05 0.05 1.0"/>
            </material>
        </visual>
        <collision>
            <origin xyz="0.545 0.04 -0.21" rpy="0 0 0"/>
            <geometry>
            <mesh filename="package://field_description/meshes/track_bot_meshes/driven_wheel_1_right.stl"
                    scale="0.001 0.001 0.001"/>
            </geometry>
        </collision>
    </link>

    <link name="driven_wheel_2_right">
        <inertial>
            <origin xyz="-0.675056 -0.07218 0.07" rpy="0 0 0"/>
            <mass value="4.342035"/>
            <inertia ixx="0.01118" iyy="0.01282" izz="0.01118"
                    ixy="4.4e-11" ixz="-4.5e-10" iyz="-1.8e-10"/>
        </inertial>
        <visual>
            <origin xyz="0.35 -0.07 0" rpy="0 0 0"/>
            <geometry>
            <mesh filename="package://field_description/meshes/track_bot_meshes/driven_wheel_2_right.stl"
                    scale="0.001 0.001 0.001"/>
            </geometry>
            <material name="black">
                <color rgba="0.05 0.05 0.05 1.0"/>
            </material>
        </visual>
        <collision>
            <origin xyz="0.35 -0.07 0" rpy="0 0 0"/>
            <geometry>
            <mesh filename="package://field_description/meshes/track_bot_meshes/driven_wheel_2_right.stl"
                    scale="0.001 0.001 0.001"/>
            </geometry>
        </collision>
    </link>

    <link name="driven_wheel_3_right">
        <inertial>
            <origin xyz="-0.845055 -0.071871 0.04" rpy="0 0 0"/>
            <mass value="1.095122"/>
            <inertia ixx="0.001617" iyy="0.000797" izz="0.001617"
                    ixy="-6.1e-16" ixz="2.9e-11" iyz="1.5e-16"/>
        </inertial>
        <visual>
            <origin xyz="0.845 0.04 -0.04" rpy="0 0 0"/>
            <geometry>
            <mesh filename="package://field_description/meshes/track_bot_meshes/driven_wheel_3_right.stl"
                    scale="0.001 0.001 0.001"/>
            </geometry>
            <material name="black">
                <color rgba="0.05 0.05 0.05 1.0"/>
            </material>
        </visual>
        <collision>
            <origin xyz="0.845 0.04 -0.04" rpy="0 0 0"/>
            <geometry>
            <mesh filename="package://field_description/meshes/track_bot_meshes/driven_wheel_3_right.stl"
                    scale="0.001 0.001 0.001"/>
            </geometry>
        </collision>
    </link>

    <link name="drive_wheel_right">
        <inertial>
            <origin xyz="-1.025 -0.071528 0.069997" rpy="0 0 0"/>
            <mass value="5.435282"/>
            <inertia ixx="0.01381" iyy="0.01734" izz="0.01381"
                    ixy="1e-12" ixz="-6.6e-15" iyz="2.1e-7"/>
        </inertial>
        <visual>
            <origin xyz="1.025 0.04 -0.07" rpy="0 0 0"/>
            <geometry>
            <mesh filename="package://field_description/meshes/track_bot_meshes/drive_wheel_right.stl"
                    scale="0.001 0.001 0.001"/>
            </geometry>
            <material name="black">
                <color rgba="0.05 0.05 0.05 1.0"/>
            </material>
        </visual>
        <collision>
            <origin xyz="0 0.04 0" rpy="0 0 0"/>
            <geometry>
            <mesh filename="package://field_description/meshes/track_bot_meshes/drive_wheel_right.stl"
                    scale="0.001 0.001 0.001"/>
            </geometry>
        </collision>
    </link>

    <link name="track_left">
        <inertial>
            <origin xyz="-1.025 -0.071528 0.069997" rpy="0 0 0"/>
            <mass value="5.435282"/>
            <inertia ixx="0.01381" iyy="0.01734" izz="0.01381"
                    ixy="1e-12" ixz="-6.6e-15" iyz="2.1e-7"/>
        </inertial>
        <visual>
            <origin xyz="-0.465 0.06 -0.095" rpy="0 -0.3 0"/>
            <geometry>
            <mesh filename="package://field_description/meshes/track_bot_meshes/track.stl"
                    scale="0.001 0.001 0.001"/>
            </geometry>
            <material name="black">
                <color rgba="0.05 0.05 0.05 1.0"/>
            </material>
        </visual>
        <collision>
            <origin xyz="0 0 0" rpy="0 0 0"/>
            <geometry>
            <mesh filename="package://field_description/meshes/track_bot_meshes/track.stl"
                    scale="0.001 0.001 0.001"/>
            </geometry>
        </collision>
    </link>

    <link name="track_right">
        <inertial>
            <origin xyz="-1.025 -0.071528 0.069997" rpy="0 0 0"/>
            <mass value="5.435282"/>
            <inertia ixx="0.01381" iyy="0.01734" izz="0.01381"
                    ixy="1e-12" ixz="-6.6e-15" iyz="2.1e-7"/>
        </inertial>
        <visual>
            <origin xyz="-0.465 -0.62 -0.095" rpy="0 -0.3 0"/>
            <geometry>
            <mesh filename="package://field_description/meshes/track_bot_meshes/track.stl"
                    scale="0.001 0.001 0.001"/>
            </geometry>
            <material name="black">
                <color rgba="0.05 0.05 0.05 1.0"/>
            </material>
        </visual>
        <collision>
            <origin xyz="0 0 0" rpy="0 0 0"/>
            <geometry>
            <mesh filename="package://field_description/meshes/track_bot_meshes/track.stl"
                    scale="0.001 0.001 0.001"/>
            </geometry>
        </collision>
    </link>

    <link name="base_link">
        <inertial>
            <!-- Center of Mass -->
            <origin xyz="-0.806932 0.28002 0.129659" rpy="0 0 0"/>

            <mass value="23.671827"/>

            <inertia
            ixx="0.9898"
            iyy="0.6294"
            izz="1.291"
            ixy="-3.945731e-05"
            ixz="-0.1658"
            iyz="3.2171403e-05"/>
        </inertial>

        <visual>
            <origin xyz="0.810194 -0.255942 0" rpy="0 0 0"/>
            <geometry>
            <mesh filename="package://field_description/meshes/track_bot_meshes/base_link.stl"
                    scale="0.001 0.001 0.001"/>
            </geometry>
            <material name="base_grey">
            <color rgba="0.5 0.5 0.5 1.0"/>
            </material>
        </visual>

        <collision>
            <origin xyz="0.810194 -0.255942 0" rpy="0 0 0"/>
            <geometry>
            <mesh filename="package://field_description/meshes/track_bot_meshes/base_link.stl"
                    scale="0.001 0.001 0.001"/>
            </geometry>
        </collision>
    </link>
    

    <link name="base_footprint"/>

    <joint name="base_link_joint" type="fixed">
        <parent link="base_footprint"/>
        <child link="base_link"/>
    </joint>

    <joint name="driver_wheel_1_left_joint" type="continuous">
        <parent link="base_link"/>
        <child link="driver_wheel_1_left"/>
        <origin xyz="0.265194 0.334058 0.21" rpy="0 0 0"/>
        <axis xyz="0 1 0"/>
    </joint>

    <joint name="driven_wheel_2_left_joint" type="continuous">
        <parent link="base_link"/>
        <child link="driven_wheel_2_left"/>
        <origin xyz="0.135138 0.334058 0.07" rpy="0 0 0"/>
        <axis xyz="0 1 0"/>
    </joint>

    <joint name="driven_wheel_3_left_joint" type="continuous">
        <parent link="base_link"/>
        <child link="driven_wheel_3_left"/>
        <origin xyz="-0.034861 0.334058 0.04" rpy="0 0 0"/>
        <axis xyz="0 1 0"/>
    </joint>

    <joint name="drive_wheel_left_joint" type="continuous">
        <parent link="base_link"/>
        <child link="drive_wheel_left"/>
        <origin xyz="-0.214806 0.334058 0.069998" rpy="0 0 0"/>
        <axis xyz="0 1 0"/>
    </joint>

    <joint name="driven_wheel_1_right_joint" type="continuous">
        <parent link="base_link"/>
        <child link="driven_wheel_1_right"/>
        <origin xyz="0.265194 -0.287942 0.21" rpy="0 0 0"/>
        <axis xyz="0 1 0"/>
    </joint>

    <joint name="driven_wheel_2_right_joint" type="continuous">
        <parent link="base_link"/>
        <child link="driven_wheel_2_right"/>
        <origin xyz="0.135138 -0.288122 0.07" rpy="0 0 0"/>
        <axis xyz="0 1 0"/>
    </joint>

    <joint name="driven_wheel_3_right_joint" type="continuous">
        <parent link="base_link"/>
        <child link="driven_wheel_3_right"/>
        <origin xyz="-0.034861 -0.287813 0.04" rpy="0 0 0"/>
        <axis xyz="0 1 0"/>
    </joint>

    <joint name="drive_wheel_right_joint" type="continuous">
        <parent link="base_link"/>
        <child link="drive_wheel_right"/>
        <origin xyz="-0.214806 -0.28747 0.069997" rpy="0 0 0"/>
        <axis xyz="0 1 0"/>
    </joint>

    <joint name="track_left_joint" type="fixed">
        <parent link="base_link"/>
        <child link="track_left"/>
    </joint>

    <joint name="track_right_joint" type="fixed">
        <parent link="base_link"/>
        <child link="track_right"/>
    </joint>

    <gazebo>
        <plugin name="gz::sim::systems::DiffDrive" filename="gz-sim-diff-drive-system">

        <!-- Wheel Information -->
        <left_joint>drive_wheel_left_joint</left_joint>
        <right_joint>drive_wheel_right_joint</right_joint>
        <wheel_separation>0.46</wheel_separation>
        <wheel_diameter>0.05</wheel_diameter>


        <!-- Limits -->
        <max_wheel_torque>100</max_wheel_torque>
        <max_wheel_acceleration>50.0</max_wheel_acceleration>

        
        <!-- Output -->
        <topic>cmd_vel</topic>
        <odometry_frame_id>/model/my_robot/odometry</odometry_frame_id>
        <robot_base_frame_id>base_link</robot_base_frame_id>

        <publish_odom>true</publish_odom>
        <publish_odom_tf>true</publish_odom_tf>
        <publish_wheel_tf>true</publish_wheel_tf>

        </plugin>
    </gazebo>


</robot>